<?xml version='1.0'?>
<sdf version='1.4'>

	<model name="wip">

		<static>false</static>

<!--- LOWER BODY STATIC START --->
		<link name='lwr_body'>
			<pose>0 0 .2 0 0 0</pose>
      <inertial>
		    <inertia>
		      <ixx>1</ixx>
		      <ixy>0</ixy>
		      <ixz>0</ixz>
		      <iyy>1</iyy>
		      <iyz>0</iyz>
		      <izz>1</izz>
		    </inertia>
      <mass>10.0</mass>
    </inertial>

			<collision name='lwr_body_collision'>
				<geometry>
					<box>
						<size>.4 .2 .3</size>
					</box>
				</geometry>
			</collision>

			<visual name='lwr_body_visual'>
				<geometry>
					<box>
						<size>.4 .2 .3</size>
					</box>
				</geometry>
			</visual>

<!--- LOWER BODY FL WHEEL START --->	
		<collision name='FL_wheel_collision'>
				<pose>0.15 -.1 -0.15 0 0 0</pose>
				<geometry>
					<sphere>
						<radius>.05</radius>
					</sphere>
				</geometry>

				<surface>
					<friction>
						<ode>
							<mu>0</mu>
							<mu2>0</mu2>
							<slip1>1.0</slip1>
							<slip2>1.0</slip2>
						</ode>
					</friction>
				</surface>
	
		</collision>

		<visual name='FL_wheel_visual'>
			<pose>0.15 -.1 -0.15 0 0 0</pose>
			<geometry>
				<sphere>
						<radius>.05</radius>
					</sphere>
			</geometry>
		</visual>
<!--- LOWER BODY FL WHEEL END --->	

<!--- LOWER BODY FR WHEEL START --->	
		<collision name='FR_wheel_collision'>
				<pose>0.15 .1 -0.15 0 0 0</pose>
				<geometry>
					<sphere>
						<radius>.05</radius>
					</sphere>
				</geometry>

				<surface>
					<friction>
						<ode>
							<mu>0</mu>
							<mu2>0</mu2>
							<slip1>1.0</slip1>
							<slip2>1.0</slip2>
						</ode>
					</friction>
				</surface>
	
		</collision>

		<visual name='FR_wheel_visual'>
			<pose>0.15 .1 -0.15 0 0 0</pose>
			<geometry>
				<sphere>
						<radius>.05</radius>
					</sphere>
			</geometry>
		</visual>
	</link>

<!--- LOWER BODY FR WHEEL END --->		
<!--- LOWER BODY STATIC END --->

<!--- LOWER BODY DYNAMIC START --->
<!--- LOWER BODY BR WHEEL START --->
	<link name="BR_wheel">	
		<pose>-0.1 0.13 0.1 0 1.5707 1.5707</pose>

		<collision name="BR_wheel_collision">
			<geometry>
				<cylinder>
						<radius>.1</radius>
						<length>0.05</length>
					</cylinder>
				</geometry>
		</collision>

		<visual name="BR_wheel_visual">
			<geometry>
				<cylinder>
						<radius>.1</radius>
						<length>0.05</length>
				</cylinder>
			</geometry>
		</visual>

	</link>
<!--- LOWER BODY BR WHEEL END --->

<!--- LOWER BODY BR WHEEL HINGE START --->	
	<joint type="revolute" name="BR_wheel_hinge">
		<pose>0 0 0 0 0 0</pose>
		<child>BR_wheel</child>
		<parent>lwr_body</parent>
		<axis>
			<xyz>0 1 0</xyz>
		</axis>
	</joint>	
<!--- LOWER BODY BR WHEEL HINGE END --->		

<!--- LOWER BODY BL WHEEL START --->
	<link name="BL_wheel">	
		<pose>-0.1 -0.13 0.1 0 1.5707 1.5707</pose>

		<collision name="BL_wheel_collision">
			<geometry>
				<cylinder>
						<radius>.1</radius>
						<length>0.05</length>
					</cylinder>
				</geometry>
		</collision>

		<visual name="BL_wheel_visual">
			<geometry>
				<cylinder>
						<radius>.1</radius>
						<length>0.05</length>
				</cylinder>
			</geometry>
		</visual>

	</link>
<!--- LOWER BODY BL WHEEL END --->

<!--- LOWER BODY BR WHEEL HINGE START --->	
	<joint type="revolute" name="BL_wheel_hinge">
		<pose>0 0 0 0 0 0</pose>
		<child>BL_wheel</child>
		<parent>lwr_body</parent>
		<axis>
			<xyz>0 1 0</xyz>
		</axis>
	</joint>	
<!--- LOWER BODY BR WHEEL HINGE END --->	
	
<!--- LOWER BODY DYNAMIC END --->


<!--- UPPER BODY START --->
		<link name='uppr_body'>
			<pose>0 0 .61 0 0 0</pose>

      <inertial>
        <inertia>
          <ixx>1</ixx>
          <ixy>0</ixy>
          <ixz>0</ixz>
          <iyy>1</iyy>
          <iyz>0</iyz>
          <izz>1</izz>
        </inertia>
        <mass>1.0</mass>
      </inertial>

			<collision name='uppr_body_collision'>
				<geometry>
					<box>
						<size>.4 .2 .5</size>
					</box>
				</geometry>
			</collision>

			<visual name='uppr_body_visual'>
				<geometry>
					<box>
						<size>.4 .2 .5</size>
					</box>
				</geometry>
			</visual>
		</link>
	<!---
	<joint type="revolute" name="hip_joint">
	--->
	<joint type="revolute" name="hip_joint">
		<pose>0 0 0.4 0 0 0</pose>
		<child>uppr_body</child>
		<parent>lwr_body</parent>
		<axis>
			<xyz>0 0 1</xyz>
			<dynamics>
					<friction>
						10000
					</friction>
			</dynamics>

		<limit>
			<upper>2.96706</upper>
			<lower>-2.96706</lower>
		</limit>
		</axis>

	</joint>	

<!--- UPPER BODY END --->

<!--- SENSORS START --->

<!--- HOKUYO START --->
    <include>
      <uri>model://hokuyo2</uri>
      <pose>0.2 0 0.4 0 0 0</pose>
    </include>
    <joint name="hokuyo_joint" type="revolute">
      <child>hokuyo2::link</child>
      <parent>uppr_body</parent>
      <axis>
        <xyz>0 0 1</xyz>
        <limit>
          <upper>0</upper>
          <lower>0</lower>
        </limit>
      </axis>
    </joint>
<!--- HOKUYO END --->

<!--- KINECT / XTION START --->
    <include>
      <uri>model://kinect2</uri>
      <pose>0.25 0 0.1 3.14159 0 0</pose>
    </include>
    <joint name="kinect_joint" type="revolute">
      <child>kinect2::link</child>
      <parent>lwr_body</parent>
      <axis>
        <xyz>0 0 1</xyz>
        <limit>
          <upper>0</upper>
          <lower>0</lower>
        </limit>
      </axis>
    </joint>
<!--- KINECT / XTION END --->

<!--- SENSORS END --->

<!--- CONTROLLER PLUGINS START --->
<plugin name='differential_drive_controller'
              filename='libgazebo_ros_diff_drive.so'>
        <alwaysOn>true</alwaysOn>
        <updateRate>100</updateRate>
        <leftJoint>BL_wheel_hinge</leftJoint>
        <rightJoint>BR_wheel_hinge</rightJoint>
        <wheelSeparation>0.26</wheelSeparation>
        <wheelDiameter>0.1</wheelDiameter>
        <torque>5</torque>
        <commandTopic>cmd_vel</commandTopic>
        <odometryTopic>odom</odometryTopic>
        <odometryFrame>odom</odometryFrame>
        <robotBaseFrame>base_link</robotBaseFrame>
</plugin>





<!--- CONTROLLER PLUGINS END --->


	</model>
</sdf>
